[INFO   ] Logger: Record log in C:\Users\wd333\.kivy\logs\kivy_19-06-20_4.txt
[INFO   ] Kivy: v1.10.1
[INFO   ] Python: v3.7.2 (tags/v3.7.2:9a3ffc0492, Dec 23 2018, 23:09:28) [MSC v.1916 64 bit (AMD64)]
[INFO   ] Factory: 194 symbols loaded
[INFO   ] Image: Providers: img_tex, img_dds, img_sdl2, img_pil, img_gif (img_ffpyplayer ignored)
[INFO   ] Window: Provider: sdl2
[INFO   ] GL: Using the "OpenGL" graphics system
[INFO   ] GL: GLEW initialization succeeded
[INFO   ] GL: Backend used <glew>
[INFO   ] GL: OpenGL version <b'4.5.0 - Build 24.20.100.6293'>
[INFO   ] GL: OpenGL vendor <b'Intel'>
[INFO   ] GL: OpenGL renderer <b'Intel(R) HD Graphics 520'>
[INFO   ] GL: OpenGL parsed version: 4, 5
[INFO   ] GL: Shading version <b'4.50 - Build 24.20.100.6293'>
[INFO   ] GL: Texture max size <16384>
[INFO   ] GL: Texture max units <32>
[WARNING] Image: Unable to load image <D:\Workspace\Oleksii Dovhaniuk\Python\CHNU\GGC_v1.0\dist\main\kivy_install\data\glsl\default.png>
[CRITICAL] Window: Unable to find any valuable Window provider.
sdl2 - Exception: SDL2: Unable to load image
  File "site-packages\kivy\core\__init__.py", line 67, in core_select_lib
  File "site-packages\kivy\core\window\window_sdl2.py", line 140, in __init__
  File "site-packages\kivy\core\window\__init__.py", line 968, in __init__
  File "site-packages\kivy\core\window\window_sdl2.py", line 294, in create_window
  File "site-packages\kivy\core\window\__init__.py", line 1216, in create_window
  File "kivy\graphics\instructions.pyx", line 759, in kivy.graphics.instructions.RenderContext.__init__
  File "site-packages\kivy\core\image\__init__.py", line 536, in __init__
  File "site-packages\kivy\core\image\__init__.py", line 732, in _set_filename
  File "site-packages\kivy\core\image\__init__.py", line 435, in load
  File "site-packages\kivy\core\image\__init__.py", line 201, in __init__
  File "site-packages\kivy\core\image\img_sdl2.py", line 41, in load

[INFO   ] Text: Provider: sdl2
[WARNING] stderr: Traceback (most recent call last):
[WARNING] stderr:   File "main.py", line 10, in <module>
[WARNING] stderr:   File "c:\users\wd333\appdata\local\programs\python\python37\lib\site-packages\PyInstaller\loader\pyimod03_importers.py", line 627, in exec_module
[WARNING] stderr:     exec(bytecode, module.__dict__)
[WARNING] stderr:   File "setUp.py", line 6, in <module>
[WARNING] stderr:   File "c:\users\wd333\appdata\local\programs\python\python37\lib\site-packages\PyInstaller\loader\pyimod03_importers.py", line 627, in exec_module
[WARNING] stderr:     exec(bytecode, module.__dict__)
[WARNING] stderr:   File "action.py", line 15, in <module>
[WARNING] stderr: ModuleNotFoundError: No module named 'kivy.garden'
